Workbook
Name ExpenseCats: Settings!$B$8:$B$37
Name IncomeCats: Settings!$D$8:$D$37
Name Accounts: Settings!$F$8:$F$37
Name Months: Settings!$H$8:$H$19

Sheet Start Here
B2: Tidy Money — Budget Dashboard
B3: Thank you for your purchase. This page gets you set up in about 10 minutes.
B5: USING GOOGLE SHEETS?
B6: 1 | C6: Upload this file to Google Drive, open it, then choose File → Save as Google Sheets. (Or in Sheets: File → Import → Upload → 'Replace spreadsheet'.) Every formula, dropdown and chart is compatible.
B7: USING EXCEL?
B8: 1 | C8: Just open the file. If Excel shows 'Protected View', click Enable Editing. Works on Mac & Windows, Excel 2016 or newer and Microsoft 365. Apple Numbers opens it too (charts may look slightly different).
B9: SET-UP (ONCE)
B10: 2 | C10: Settings tab → set your budget year and edit the category and account lists to match your life. Keep names short.
B11: 3 | C11: Budget Plan tab → type a default monthly amount for each income and expense category. Any single month can be overwritten later.
B12: 4 | C12: Transactions tab → delete the example rows (they say 'example' in Notes) and start logging. Date, description, Income/Expense, category, amount. That's it.
B13: EVERY WEEK (5 MINUTES)
B14: 5 | C14: Add your transactions. Open the Dashboard, pick the month in the yellow dropdown, and see what's left in each category.
B15: 6 | C15: Savings Goals → update 'Saved so far'. Debt Payoff → update balances. Net Worth → once a month, type your balances.
B16: GOOD TO KNOW
B17: • | C17: Yellow cells are for you to type in. White and green cells are formulas — leave them alone (if you break one, just undo).
B18: • | C18: Savings rate = (income − expenses) ÷ income for the selected month. 'Savings transfers' counts as an expense so money you move to savings isn't double-counted.
B19: • | C19: Couples: share the Google Sheet with your partner; you can both log from your phones with the Google Sheets app.
B20: • | C20: New year? Save a copy, change the year in Settings, clear the Transactions rows, and keep your plan.
B21: • | C21: Need help or a refund within 7 days? Reply to your Whop receipt email.
C23: © Tidy Money. For personal use. Please don't resell or redistribute this file.

Sheet Dashboard
B2: Tidy Money — Budget Dashboard
B3: Pick a month → | C3: =DATE(Settings!$C$5,9,1) | E3: (dropdown – all tabs marked 'selected month' follow this cell)
C5: Income this month | F5: Spent this month | I5: Left over | L5: Savings rate
C6: =SUMIFS(Transactions!$F$7:$F$1006,Transactions!$D$7:$D$1006,"Income",Transactions!$I$7:$I$1006,Dashboard!$C$3) | F6: =SUMIFS(Transactions!$F$7:$F$1006,Transactions!$D$7:$D$1006,"Expense",Transactions!$I$7:$I$1006,Dashboard!$C$3) | I6: =C6-F6 | L6: =IF(C6=0,0,I6/C6)
C8: Planned expenses | F8: Actual vs plan | I8: Planned income | L8: Transactions logged
C9: =IFERROR(INDEX('Budget Plan'!$D$51:$O$51,MATCH(Dashboard!$C$3,'Budget Plan'!$D$6:$O$6,0)),0) | F9: =F6-C9 | I9: =IFERROR(INDEX('Budget Plan'!$D$18:$O$18,MATCH(Dashboard!$C$3,'Budget Plan'!$D$6:$O$6,0)),0) | L9: =COUNTIFS(Transactions!$I$7:$I$1006,Dashboard!$C$3)
C11: Category | D11: Planned | E11: Actual | F11: Left | G11: % used | I11: Top spending | J11: Amount
C12: =IF(Settings!B8="","",Settings!B8) | D12: =IF($C12="","",IFERROR(INDEX('Budget Plan'!$D$21:$O$21,MATCH(Dashboard!$C$3,'Budget Plan'!$D$6:$O$6,0)),0)) | E12: =IF($C12="","",SUMIFS(Transactions!$F$7:$F$1006,Transactions!$D$7:$D$1006,"Expense",Transactions!$E$7:$E$1006,$C12,Transactions!$I$7:$I$1006,Dashboard!$C$3)) | F12: =IF($C12="","",D12-E12) | G12: =IF($C12="","",IF(D12=0,IF(E12>0,1,0),E12/D12)) | I12: =IFERROR(INDEX($C$12:$C$41,MATCH(LARGE($E$12:$E$41,1),$E$12:$E$41,0)),"") | J12: =IFERROR(LARGE($E$12:$E$41,1),"")
C13: =IF(Settings!B9="","",Settings!B9) | D13: =IF($C13="","",IFERROR(INDEX('Budget Plan'!$D$22:$O$22,MATCH(Dashboard!$C$3,'Budget Plan'!$D$6:$O$6,0)),0)) | E13: =IF($C13="","",SUMIFS(Transactions!$F$7:$F$1006,Transactions!$D$7:$D$1006,"Expense",Transactions!$E$7:$E$1006,$C13,Transactions!$I$7:$I$1006,Dashboard!$C$3)) | F13: =IF($C13="","",D13-E13) | G13: =IF($C13="","",IF(D13=0,IF(E13>0,1,0),E13/D13)) | I13: =IFERROR(INDEX($C$12:$C$41,MATCH(LARGE($E$12:$E$41,2),$E$12:$E$41,0)),"") | J13: =IFERROR(LARGE($E$12:$E$41,2),"")
C14: =IF(Settings!B10="","",Settings!B10) | D14: =IF($C14="","",IFERROR(INDEX('Budget Plan'!$D$23:$O$23,MATCH(Dashboard!$C$3,'Budget Plan'!$D$6:$O$6,0)),0)) | E14: =IF($C14="","",SUMIFS(Transactions!$F$7:$F$1006,Transactions!$D$7:$D$1006,"Expense",Transactions!$E$7:$E$1006,$C14,Transactions!$I$7:$I$1006,Dashboard!$C$3)) | F14: =IF($C14="","",D14-E14) | G14: =IF($C14="","",IF(D14=0,IF(E14>0,1,0),E14/D14)) | I14: =IFERROR(INDEX($C$12:$C$41,MATCH(LARGE($E$12:$E$41,3),$E$12:$E$41,0)),"") | J14: =IFERROR(LARGE($E$12:$E$41,3),"")
C15: =IF(Settings!B11="","",Settings!B11) | D15: =IF($C15="","",IFERROR(INDEX('Budget Plan'!$D$24:$O$24,MATCH(Dashboard!$C$3,'Budget Plan'!$D$6:$O$6,0)),0)) | E15: =IF($C15="","",SUMIFS(Transactions!$F$7:$F$1006,Transactions!$D$7:$D$1006,"Expense",Transactions!$E$7:$E$1006,$C15,Transactions!$I$7:$I$1006,Dashboard!$C$3)) | F15: =IF($C15="","",D15-E15) | G15: =IF($C15="","",IF(D15=0,IF(E15>0,1,0),E15/D15)) | I15: =IFERROR(INDEX($C$12:$C$41,MATCH(LARGE($E$12:$E$41,4),$E$12:$E$41,0)),"") | J15: =IFERROR(LARGE($E$12:$E$41,4),"")
C16: =IF(Settings!B12="","",Settings!B12) | D16: =IF($C16="","",IFERROR(INDEX('Budget Plan'!$D$25:$O$25,MATCH(Dashboard!$C$3,'Budget Plan'!$D$6:$O$6,0)),0)) | E16: =IF($C16="","",SUMIFS(Transactions!$F$7:$F$1006,Transactions!$D$7:$D$1006,"Expense",Transactions!$E$7:$E$1006,$C16,Transactions!$I$7:$I$1006,Dashboard!$C$3)) | F16: =IF($C16="","",D16-E16) | G16: =IF($C16="","",IF(D16=0,IF(E16>0,1,0),E16/D16)) | I16: =IFERROR(INDEX($C$12:$C$41,MATCH(LARGE($E$12:$E$41,5),$E$12:$E$41,0)),"") | J16: =IFERROR(LARGE($E$12:$E$41,5),"")
C17: =IF(Settings!B13="","",Settings!B13) | D17: =IF($C17="","",IFERROR(INDEX('Budget Plan'!$D$26:$O$26,MATCH(Dashboard!$C$3,'Budget Plan'!$D$6:$O$6,0)),0)) | E17: =IF($C17="","",SUMIFS(Transactions!$F$7:$F$1006,Transactions!$D$7:$D$1006,"Expense",Transactions!$E$7:$E$1006,$C17,Transactions!$I$7:$I$1006,Dashboard!$C$3)) | F17: =IF($C17="","",D17-E17) | G17: =IF($C17="","",IF(D17=0,IF(E17>0,1,0),E17/D17))
C18: =IF(Settings!B14="","",Settings!B14) | D18: =IF($C18="","",IFERROR(INDEX('Budget Plan'!$D$27:$O$27,MATCH(Dashboard!$C$3,'Budget Plan'!$D$6:$O$6,0)),0)) | E18: =IF($C18="","",SUMIFS(Transactions!$F$7:$F$1006,Transactions!$D$7:$D$1006,"Expense",Transactions!$E$7:$E$1006,$C18,Transactions!$I$7:$I$1006,Dashboard!$C$3)) | F18: =IF($C18="","",D18-E18) | G18: =IF($C18="","",IF(D18=0,IF(E18>0,1,0),E18/D18)) | I18: Note: if two categories tie, the first one is shown twice – that's normal for LARGE/MATCH.
C19: =IF(Settings!B15="","",Settings!B15) | D19: =IF($C19="","",IFERROR(INDEX('Budget Plan'!$D$28:$O$28,MATCH(Dashboard!$C$3,'Budget Plan'!$D$6:$O$6,0)),0)) | E19: =IF($C19="","",SUMIFS(Transactions!$F$7:$F$1006,Transactions!$D$7:$D$1006,"Expense",Transactions!$E$7:$E$1006,$C19,Transactions!$I$7:$I$1006,Dashboard!$C$3)) | F19: =IF($C19="","",D19-E19) | G19: =IF($C19="","",IF(D19=0,IF(E19>0,1,0),E19/D19))
C20: =IF(Settings!B16="","",Settings!B16) | D20: =IF($C20="","",IFERROR(INDEX('Budget Plan'!$D$29:$O$29,MATCH(Dashboard!$C$3,'Budget Plan'!$D$6:$O$6,0)),0)) | E20: =IF($C20="","",SUMIFS(Transactions!$F$7:$F$1006,Transactions!$D$7:$D$1006,"Expense",Transactions!$E$7:$E$1006,$C20,Transactions!$I$7:$I$1006,Dashboard!$C$3)) | F20: =IF($C20="","",D20-E20) | G20: =IF($C20="","",IF(D20=0,IF(E20>0,1,0),E20/D20))
C21: =IF(Settings!B17="","",Settings!B17) | D21: =IF($C21="","",IFERROR(INDEX('Budget Plan'!$D$30:$O$30,MATCH(Dashboard!$C$3,'Budget Plan'!$D$6:$O$6,0)),0)) | E21: =IF($C21="","",SUMIFS(Transactions!$F$7:$F$1006,Transactions!$D$7:$D$1006,"Expense",Transactions!$E$7:$E$1006,$C21,Transactions!$I$7:$I$1006,Dashboard!$C$3)) | F21: =IF($C21="","",D21-E21) | G21: =IF($C21="","",IF(D21=0,IF(E21>0,1,0),E21/D21))
C22: =IF(Settings!B18="","",Settings!B18) | D22: =IF($C22="","",IFERROR(INDEX('Budget Plan'!$D$31:$O$31,MATCH(Dashboard!$C$3,'Budget Plan'!$D$6:$O$6,0)),0)) | E22: =IF($C22="","",SUMIFS(Transactions!$F$7:$F$1006,Transactions!$D$7:$D$1006,"Expense",Transactions!$E$7:$E$1006,$C22,Transactions!$I$7:$I$1006,Dashboard!$C$3)) | F22: =IF($C22="","",D22-E22) | G22: =IF($C22="","",IF(D22=0,IF(E22>0,1,0),E22/D22))
C23: =IF(Settings!B19="","",Settings!B19) | D23: =IF($C23="","",IFERROR(INDEX('Budget Plan'!$D$32:$O$32,MATCH(Dashboard!$C$3,'Budget Plan'!$D$6:$O$6,0)),0)) | E23: =IF($C23="","",SUMIFS(Transactions!$F$7:$F$1006,Transactions!$D$7:$D$1006,"Expense",Transactions!$E$7:$E$1006,$C23,Transactions!$I$7:$I$1006,Dashboard!$C$3)) | F23: =IF($C23="","",D23-E23) | G23: =IF($C23="","",IF(D23=0,IF(E23>0,1,0),E23/D23))
C24: =IF(Settings!B20="","",Settings!B20) | D24: =IF($C24="","",IFERROR(INDEX('Budget Plan'!$D$33:$O$33,MATCH(Dashboard!$C$3,'Budget Plan'!$D$6:$O$6,0)),0)) | E24: =IF($C24="","",SUMIFS(Transactions!$F$7:$F$1006,Transactions!$D$7:$D$1006,"Expense",Transactions!$E$7:$E$1006,$C24,Transactions!$I$7:$I$1006,Dashboard!$C$3)) | F24: =IF($C24="","",D24-E24) | G24: =IF($C24="","",IF(D24=0,IF(E24>0,1,0),E24/D24))
C25: =IF(Settings!B21="","",Settings!B21) | D25: =IF($C25="","",IFERROR(INDEX('Budget Plan'!$D$34:$O$34,MATCH(Dashboard!$C$3,'Budget Plan'!$D$6:$O$6,0)),0)) | E25: =IF($C25="","",SUMIFS(Transactions!$F$7:$F$1006,Transactions!$D$7:$D$1006,"Expense",Transactions!$E$7:$E$1006,$C25,Transactions!$I$7:$I$1006,Dashboard!$C$3)) | F25: =IF($C25="","",D25-E25) | G25: =IF($C25="","",IF(D25=0,IF(E25>0,1,0),E25/D25))
C26: =IF(Settings!B22="","",Settings!B22) | D26: =IF($C26="","",IFERROR(INDEX('Budget Plan'!$D$35:$O$35,MATCH(Dashboard!$C$3,'Budget Plan'!$D$6:$O$6,0)),0)) | E26: =IF($C26="","",SUMIFS(Transactions!$F$7:$F$1006,Transactions!$D$7:$D$1006,"Expense",Transactions!$E$7:$E$1006,$C26,Transactions!$I$7:$I$1006,Dashboard!$C$3)) | F26: =IF($C26="","",D26-E26) | G26: =IF($C26="","",IF(D26=0,IF(E26>0,1,0),E26/D26))
C27: =IF(Settings!B23="","",Settings!B23) | D27: =IF($C27="","",IFERROR(INDEX('Budget Plan'!$D$36:$O$36,MATCH(Dashboard!$C$3,'Budget Plan'!$D$6:$O$6,0)),0)) | E27: =IF($C27="","",SUMIFS(Transactions!$F$7:$F$1006,Transactions!$D$7:$D$1006,"Expense",Transactions!$E$7:$E$1006,$C27,Transactions!$I$7:$I$1006,Dashboard!$C$3)) | F27: =IF($C27="","",D27-E27) | G27: =IF($C27="","",IF(D27=0,IF(E27>0,1,0),E27/D27))
C28: =IF(Settings!B24="","",Settings!B24) | D28: =IF($C28="","",IFERROR(INDEX('Budget Plan'!$D$37:$O$37,MATCH(Dashboard!$C$3,'Budget Plan'!$D$6:$O$6,0)),0)) | E28: =IF($C28="","",SUMIFS(Transactions!$F$7:$F$1006,Transactions!$D$7:$D$1006,"Expense",Transactions!$E$7:$E$1006,$C28,Transactions!$I$7:$I$1006,Dashboard!$C$3)) | F28: =IF($C28="","",D28-E28) | G28: =IF($C28="","",IF(D28=0,IF(E28>0,1,0),E28/D28))
C29: =IF(Settings!B25="","",Settings!B25) | D29: =IF($C29="","",IFERROR(INDEX('Budget Plan'!$D$38:$O$38,MATCH(Dashboard!$C$3,'Budget Plan'!$D$6:$O$6,0)),0)) | E29: =IF($C29="","",SUMIFS(Transactions!$F$7:$F$1006,Transactions!$D$7:$D$1006,"Expense",Transactions!$E$7:$E$1006,$C29,Transactions!$I$7:$I$1006,Dashboard!$C$3)) | F29: =IF($C29="","",D29-E29) | G29: =IF($C29="","",IF(D29=0,IF(E29>0,1,0),E29/D29))
C30: =IF(Settings!B26="","",Settings!B26) | D30: =IF($C30="","",IFERROR(INDEX('Budget Plan'!$D$39:$O$39,MATCH(Dashboard!$C$3,'Budget Plan'!$D$6:$O$6,0)),0)) | E30: =IF($C30="","",SUMIFS(Transactions!$F$7:$F$1006,Transactions!$D$7:$D$1006,"Expense",Transactions!$E$7:$E$1006,$C30,Transactions!$I$7:$I$1006,Dashboard!$C$3)) | F30: =IF($C30="","",D30-E30) | G30: =IF($C30="","",IF(D30=0,IF(E30>0,1,0),E30/D30))
C31: =IF(Settings!B27="","",Settings!B27) | D31: =IF($C31="","",IFERROR(INDEX('Budget Plan'!$D$40:$O$40,MATCH(Dashboard!$C$3,'Budget Plan'!$D$6:$O$6,0)),0)) | E31: =IF($C31="","",SUMIFS(Transactions!$F$7:$F$1006,Transactions!$D$7:$D$1006,"Expense",Transactions!$E$7:$E$1006,$C31,Transactions!$I$7:$I$1006,Dashboard!$C$3)) | F31: =IF($C31="","",D31-E31) | G31: =IF($C31="","",IF(D31=0,IF(E31>0,1,0),E31/D31))
C32: =IF(Settings!B28="","",Settings!B28) | D32: =IF($C32="","",IFERROR(INDEX('Budget Plan'!$D$41:$O$41,MATCH(Dashboard!$C$3,'Budget Plan'!$D$6:$O$6,0)),0)) | E32: =IF($C32="","",SUMIFS(Transactions!$F$7:$F$1006,Transactions!$D$7:$D$1006,"Expense",Transactions!$E$7:$E$1006,$C32,Transactions!$I$7:$I$1006,Dashboard!$C$3)) | F32: =IF($C32="","",D32-E32) | G32: =IF($C32="","",IF(D32=0,IF(E32>0,1,0),E32/D32))
C33: =IF(Settings!B29="","",Settings!B29) | D33: =IF($C33="","",IFERROR(INDEX('Budget Plan'!$D$42:$O$42,MATCH(Dashboard!$C$3,'Budget Plan'!$D$6:$O$6,0)),0)) | E33: =IF($C33="","",SUMIFS(Transactions!$F$7:$F$1006,Transactions!$D$7:$D$1006,"Expense",Transactions!$E$7:$E$1006,$C33,Transactions!$I$7:$I$1006,Dashboard!$C$3)) | F33: =IF($C33="","",D33-E33) | G33: =IF($C33="","",IF(D33=0,IF(E33>0,1,0),E33/D33))
C34: =IF(Settings!B30="","",Settings!B30) | D34: =IF($C34="","",IFERROR(INDEX('Budget Plan'!$D$43:$O$43,MATCH(Dashboard!$C$3,'Budget Plan'!$D$6:$O$6,0)),0)) | E34: =IF($C34="","",SUMIFS(Transactions!$F$7:$F$1006,Transactions!$D$7:$D$1006,"Expense",Transactions!$E$7:$E$1006,$C34,Transactions!$I$7:$I$1006,Dashboard!$C$3)) | F34: =IF($C34="","",D34-E34) | G34: =IF($C34="","",IF(D34=0,IF(E34>0,1,0),E34/D34))
C35: =IF(Settings!B31="","",Settings!B31) | D35: =IF($C35="","",IFERROR(INDEX('Budget Plan'!$D$44:$O$44,MATCH(Dashboard!$C$3,'Budget Plan'!$D$6:$O$6,0)),0)) | E35: =IF($C35="","",SUMIFS(Transactions!$F$7:$F$1006,Transactions!$D$7:$D$1006,"Expense",Transactions!$E$7:$E$1006,$C35,Transactions!$I$7:$I$1006,Dashboard!$C$3)) | F35: =IF($C35="","",D35-E35) | G35: =IF($C35="","",IF(D35=0,IF(E35>0,1,0),E35/D35))
C36: =IF(Settings!B32="","",Settings!B32) | D36: =IF($C36="","",IFERROR(INDEX('Budget Plan'!$D$45:$O$45,MATCH(Dashboard!$C$3,'Budget Plan'!$D$6:$O$6,0)),0)) | E36: =IF($C36="","",SUMIFS(Transactions!$F$7:$F$1006,Transactions!$D$7:$D$1006,"Expense",Transactions!$E$7:$E$1006,$C36,Transactions!$I$7:$I$1006,Dashboard!$C$3)) | F36: =IF($C36="","",D36-E36) | G36: =IF($C36="","",IF(D36=0,IF(E36>0,1,0),E36/D36))
C37: =IF(Settings!B33="","",Settings!B33) | D37: =IF($C37="","",IFERROR(INDEX('Budget Plan'!$D$46:$O$46,MATCH(Dashboard!$C$3,'Budget Plan'!$D$6:$O$6,0)),0)) | E37: =IF($C37="","",SUMIFS(Transactions!$F$7:$F$1006,Transactions!$D$7:$D$1006,"Expense",Transactions!$E$7:$E$1006,$C37,Transactions!$I$7:$I$1006,Dashboard!$C$3)) | F37: =IF($C37="","",D37-E37) | G37: =IF($C37="","",IF(D37=0,IF(E37>0,1,0),E37/D37))
C38: =IF(Settings!B34="","",Settings!B34) | D38: =IF($C38="","",IFERROR(INDEX('Budget Plan'!$D$47:$O$47,MATCH(Dashboard!$C$3,'Budget Plan'!$D$6:$O$6,0)),0)) | E38: =IF($C38="","",SUMIFS(Transactions!$F$7:$F$1006,Transactions!$D$7:$D$1006,"Expense",Transactions!$E$7:$E$1006,$C38,Transactions!$I$7:$I$1006,Dashboard!$C$3)) | F38: =IF($C38="","",D38-E38) | G38: =IF($C38="","",IF(D38=0,IF(E38>0,1,0),E38/D38))
C39: =IF(Settings!B35="","",Settings!B35) | D39: =IF($C39="","",IFERROR(INDEX('Budget Plan'!$D$48:$O$48,MATCH(Dashboard!$C$3,'Budget Plan'!$D$6:$O$6,0)),0)) | E39: =IF($C39="","",SUMIFS(Transactions!$F$7:$F$1006,Transactions!$D$7:$D$1006,"Expense",Transactions!$E$7:$E$1006,$C39,Transactions!$I$7:$I$1006,Dashboard!$C$3)) | F39: =IF($C39="","",D39-E39) | G39: =IF($C39="","",IF(D39=0,IF(E39>0,1,0),E39/D39))
C40: =IF(Settings!B36="","",Settings!B36) | D40: =IF($C40="","",IFERROR(INDEX('Budget Plan'!$D$49:$O$49,MATCH(Dashboard!$C$3,'Budget Plan'!$D$6:$O$6,0)),0)) | E40: =IF($C40="","",SUMIFS(Transactions!$F$7:$F$1006,Transactions!$D$7:$D$1006,"Expense",Transactions!$E$7:$E$1006,$C40,Transactions!$I$7:$I$1006,Dashboard!$C$3)) | F40: =IF($C40="","",D40-E40) | G40: =IF($C40="","",IF(D40=0,IF(E40>0,1,0),E40/D40))
C41: =IF(Settings!B37="","",Settings!B37) | D41: =IF($C41="","",IFERROR(INDEX('Budget Plan'!$D$50:$O$50,MATCH(Dashboard!$C$3,'Budget Plan'!$D$6:$O$6,0)),0)) | E41: =IF($C41="","",SUMIFS(Transactions!$F$7:$F$1006,Transactions!$D$7:$D$1006,"Expense",Transactions!$E$7:$E$1006,$C41,Transactions!$I$7:$I$1006,Dashboard!$C$3)) | F41: =IF($C41="","",D41-E41) | G41: =IF($C41="","",IF(D41=0,IF(E41>0,1,0),E41/D41))
C42: Total | D42: =SUM(D12:D41) | E42: =SUM(E12:E41) | F42: =SUM(F12:F41) | G42: =IF(D42=0,0,E42/D42)

Sheet Monthly Budget
B2: Monthly Budget
B3: Selected month (change it on the Dashboard): | E3: =Dashboard!$C$3
B5: Income | C5: Planned | D5: Actual | E5: Difference
B6: =IF(Settings!D8="","",Settings!D8) | C6: =IF($B6="","",IFERROR(INDEX('Budget Plan'!$D$8:$O$8,MATCH(Dashboard!$C$3,'Budget Plan'!$D$6:$O$6,0)),0)) | D6: =IF($B6="","",SUMIFS(Transactions!$F$7:$F$1006,Transactions!$D$7:$D$1006,"Income",Transactions!$E$7:$E$1006,$B6,Transactions!$I$7:$I$1006,Dashboard!$C$3)) | E6: =IF($B6="","",D6-C6)
B7: =IF(Settings!D9="","",Settings!D9) | C7: =IF($B7="","",IFERROR(INDEX('Budget Plan'!$D$9:$O$9,MATCH(Dashboard!$C$3,'Budget Plan'!$D$6:$O$6,0)),0)) | D7: =IF($B7="","",SUMIFS(Transactions!$F$7:$F$1006,Transactions!$D$7:$D$1006,"Income",Transactions!$E$7:$E$1006,$B7,Transactions!$I$7:$I$1006,Dashboard!$C$3)) | E7: =IF($B7="","",D7-C7)
B8: =IF(Settings!D10="","",Settings!D10) | C8: =IF($B8="","",IFERROR(INDEX('Budget Plan'!$D$10:$O$10,MATCH(Dashboard!$C$3,'Budget Plan'!$D$6:$O$6,0)),0)) | D8: =IF($B8="","",SUMIFS(Transactions!$F$7:$F$1006,Transactions!$D$7:$D$1006,"Income",Transactions!$E$7:$E$1006,$B8,Transactions!$I$7:$I$1006,Dashboard!$C$3)) | E8: =IF($B8="","",D8-C8)
B9: =IF(Settings!D11="","",Settings!D11) | C9: =IF($B9="","",IFERROR(INDEX('Budget Plan'!$D$11:$O$11,MATCH(Dashboard!$C$3,'Budget Plan'!$D$6:$O$6,0)),0)) | D9: =IF($B9="","",SUMIFS(Transactions!$F$7:$F$1006,Transactions!$D$7:$D$1006,"Income",Transactions!$E$7:$E$1006,$B9,Transactions!$I$7:$I$1006,Dashboard!$C$3)) | E9: =IF($B9="","",D9-C9)
B10: =IF(Settings!D12="","",Settings!D12) | C10: =IF($B10="","",IFERROR(INDEX('Budget Plan'!$D$12:$O$12,MATCH(Dashboard!$C$3,'Budget Plan'!$D$6:$O$6,0)),0)) | D10: =IF($B10="","",SUMIFS(Transactions!$F$7:$F$1006,Transactions!$D$7:$D$1006,"Income",Transactions!$E$7:$E$1006,$B10,Transactions!$I$7:$I$1006,Dashboard!$C$3)) | E10: =IF($B10="","",D10-C10)
B11: =IF(Settings!D13="","",Settings!D13) | C11: =IF($B11="","",IFERROR(INDEX('Budget Plan'!$D$13:$O$13,MATCH(Dashboard!$C$3,'Budget Plan'!$D$6:$O$6,0)),0)) | D11: =IF($B11="","",SUMIFS(Transactions!$F$7:$F$1006,Transactions!$D$7:$D$1006,"Income",Transactions!$E$7:$E$1006,$B11,Transactions!$I$7:$I$1006,Dashboard!$C$3)) | E11: =IF($B11="","",D11-C11)
B12: =IF(Settings!D14="","",Settings!D14) | C12: =IF($B12="","",IFERROR(INDEX('Budget Plan'!$D$14:$O$14,MATCH(Dashboard!$C$3,'Budget Plan'!$D$6:$O$6,0)),0)) | D12: =IF($B12="","",SUMIFS(Transactions!$F$7:$F$1006,Transactions!$D$7:$D$1006,"Income",Transactions!$E$7:$E$1006,$B12,Transactions!$I$7:$I$1006,Dashboard!$C$3)) | E12: =IF($B12="","",D12-C12)
B13: =IF(Settings!D15="","",Settings!D15) | C13: =IF($B13="","",IFERROR(INDEX('Budget Plan'!$D$15:$O$15,MATCH(Dashboard!$C$3,'Budget Plan'!$D$6:$O$6,0)),0)) | D13: =IF($B13="","",SUMIFS(Transactions!$F$7:$F$1006,Transactions!$D$7:$D$1006,"Income",Transactions!$E$7:$E$1006,$B13,Transactions!$I$7:$I$1006,Dashboard!$C$3)) | E13: =IF($B13="","",D13-C13)
B14: =IF(Settings!D16="","",Settings!D16) | C14: =IF($B14="","",IFERROR(INDEX('Budget Plan'!$D$16:$O$16,MATCH(Dashboard!$C$3,'Budget Plan'!$D$6:$O$6,0)),0)) | D14: =IF($B14="","",SUMIFS(Transactions!$F$7:$F$1006,Transactions!$D$7:$D$1006,"Income",Transactions!$E$7:$E$1006,$B14,Transactions!$I$7:$I$1006,Dashboard!$C$3)) | E14: =IF($B14="","",D14-C14)
B15: =IF(Settings!D17="","",Settings!D17) | C15: =IF($B15="","",IFERROR(INDEX('Budget Plan'!$D$17:$O$17,MATCH(Dashboard!$C$3,'Budget Plan'!$D$6:$O$6,0)),0)) | D15: =IF($B15="","",SUMIFS(Transactions!$F$7:$F$1006,Transactions!$D$7:$D$1006,"Income",Transactions!$E$7:$E$1006,$B15,Transactions!$I$7:$I$1006,Dashboard!$C$3)) | E15: =IF($B15="","",D15-C15)
B16: Total income | C16: =SUM(C6:C15) | D16: =SUM(D6:D15) | E16: =SUM(E6:E15)
B18: Expenses | C18: Planned | D18: Actual | E18: Left to spend | F18: % used
B19: =Dashboard!C12 | C19: =Dashboard!D12 | D19: =Dashboard!E12 | E19: =Dashboard!F12 | F19: =Dashboard!G12
B20: =Dashboard!C13 | C20: =Dashboard!D13 | D20: =Dashboard!E13 | E20: =Dashboard!F13 | F20: =Dashboard!G13
B21: =Dashboard!C14 | C21: =Dashboard!D14 | D21: =Dashboard!E14 | E21: =Dashboard!F14 | F21: =Dashboard!G14
B22: =Dashboard!C15 | C22: =Dashboard!D15 | D22: =Dashboard!E15 | E22: =Dashboard!F15 | F22: =Dashboard!G15
B23: =Dashboard!C16 | C23: =Dashboard!D16 | D23: =Dashboard!E16 | E23: =Dashboard!F16 | F23: =Dashboard!G16
B24: =Dashboard!C17 | C24: =Dashboard!D17 | D24: =Dashboard!E17 | E24: =Dashboard!F17 | F24: =Dashboard!G17
B25: =Dashboard!C18 | C25: =Dashboard!D18 | D25: =Dashboard!E18 | E25: =Dashboard!F18 | F25: =Dashboard!G18
B26: =Dashboard!C19 | C26: =Dashboard!D19 | D26: =Dashboard!E19 | E26: =Dashboard!F19 | F26: =Dashboard!G19
B27: =Dashboard!C20 | C27: =Dashboard!D20 | D27: =Dashboard!E20 | E27: =Dashboard!F20 | F27: =Dashboard!G20
B28: =Dashboard!C21 | C28: =Dashboard!D21 | D28: =Dashboard!E21 | E28: =Dashboard!F21 | F28: =Dashboard!G21
B29: =Dashboard!C22 | C29: =Dashboard!D22 | D29: =Dashboard!E22 | E29: =Dashboard!F22 | F29: =Dashboard!G22
B30: =Dashboard!C23 | C30: =Dashboard!D23 | D30: =Dashboard!E23 | E30: =Dashboard!F23 | F30: =Dashboard!G23
... B48: =Dashboard!C41 | C48: =Dashboard!D41 | D48: =Dashboard!E41 | E48: =Dashboard!F41 | F48: =Dashboard!G41
B49: Total expenses | C49: =SUM(C19:C48) | D49: =SUM(D19:D48) | E49: =SUM(E19:E48) | F49: =IF(C49=0,0,D49/C49)
B51: Left over (actual) | D51: =D16-D49
B52: Left over (planned) | D52: =C16-C49

Sheet Settings
B2: Settings
B3: Edit these lists once. Every dropdown in the workbook updates automatically.
B5: Budget year | C5: 2026 | D5: ← change the year and every month in the workbook follows
B7: Expense categories | D7: Income categories | F7: Accounts | H7: Months (auto) | J7: All categories (auto)
B8: Housing | D8: Salary | F8: Checking | H8: =DATE($C$5,1,1) | J8: =IF(B8="","",B8)
B9: Utilities | D9: Partner salary | F9: Savings | H9: =DATE($C$5,2,1) | J9: =IF(B9="","",B9)
B10: Groceries | D10: Side income | F10: Credit card | H10: =DATE($C$5,3,1) | J10: =IF(B10="","",B10)
B11: Eating out | D11: Refunds | F11: Cash | H11: =DATE($C$5,4,1) | J11: =IF(B11="","",B11)
B12: Transport | D12: Other income | H12: =DATE($C$5,5,1) | J12: =IF(B12="","",B12)
B13: Insurance | H13: =DATE($C$5,6,1) | J13: =IF(B13="","",B13)
B14: Health | H14: =DATE($C$5,7,1) | J14: =IF(B14="","",B14)
B15: Subscriptions | H15: =DATE($C$5,8,1) | J15: =IF(B15="","",B15)
B16: Phone & internet | H16: =DATE($C$5,9,1) | J16: =IF(B16="","",B16)
B17: Shopping | H17: =DATE($C$5,10,1) | J17: =IF(B17="","",B17)
B18: Personal care | H18: =DATE($C$5,11,1) | J18: =IF(B18="","",B18)
B19: Kids & family | H19: =DATE($C$5,12,1) | J19: =IF(B19="","",B19)
B20: Pets | J20: =IF(B20="","",B20)
B21: Gifts & giving | J21: =IF(B21="","",B21)
B22: Fun & hobbies | J22: =IF(B22="","",B22)
B23: Travel | J23: =IF(B23="","",B23)
B24: Education | J24: =IF(B24="","",B24)
B25: Debt payments | J25: =IF(B25="","",B25)
B26: Savings transfers | J26: =IF(B26="","",B26)
B27: Other | J27: =IF(B27="","",B27)
J28: =IF(B28="","",B28)
J29: =IF(B29="","",B29)
J30: =IF(B30="","",B30)
J31: =IF(B31="","",B31)
J32: =IF(B32="","",B32)
J33: =IF(B33="","",B33)
J34: =IF(B34="","",B34)
J35: =IF(B35="","",B35)
J36: =IF(B36="","",B36)
J37: =IF(B37="","",B37)
J38: =IF(D8="","",D8)
J39: =IF(D9="","",D9)
B40: Tip: keep category names short. If you rename a category, also update it in Transactions and Budget Plan (Find & Replace). | J40: =IF(D10="","",D10)
J41: =IF(D11="","",D11)
J42: =IF(D12="","",D12)
J43: =IF(D13="","",D13)
...

Sheet Transactions
B2: Transactions
B3: Log every income and expense here. Yellow cells are yours to fill; the rest is automatic.
B6: Date | C6: Description | D6: Type | E6: Category | F6: Amount | G6: Account | H6: Notes | I6: Month (auto)
B7: 46266 | C7: Paycheck | D7: Income | E7: Salary | F7: 3200 | G7: Checking | H7: example row – delete me | I7: =IF(B7="","",DATE(YEAR(B7),MONTH(B7),1))
B8: 46266 | C8: Rent | D8: Expense | E8: Housing | F8: 1450 | G8: Checking | H8: example | I8: =IF(B8="","",DATE(YEAR(B8),MONTH(B8),1))
B9: 46268 | C9: Grocery run | D9: Expense | E9: Groceries | F9: 128.4 | G9: Credit card | H9: example | I9: =IF(B9="","",DATE(YEAR(B9),MONTH(B9),1))
B10: 46269 | C10: Electric bill | D10: Expense | E10: Utilities | F10: 96.1 | G10: Checking | H10: example | I10: =IF(B10="","",DATE(YEAR(B10),MONTH(B10),1))
B11: 46271 | C11: Gas | D11: Expense | E11: Transport | F11: 52 | G11: Credit card | H11: example | I11: =IF(B11="","",DATE(YEAR(B11),MONTH(B11),1))
B12: 46272 | C12: Streaming | D12: Expense | E12: Subscriptions | F12: 15.99 | G12: Credit card | H12: example | I12: =IF(B12="","",DATE(YEAR(B12),MONTH(B12),1))
B13: 46274 | C13: Dinner out | D13: Expense | E13: Eating out | F13: 64.3 | G13: Credit card | H13: example | I13: =IF(B13="","",DATE(YEAR(B13),MONTH(B13),1))
B14: 46277 | C14: Freelance invoice | D14: Income | E14: Side income | F14: 450 | G14: Checking | H14: example | I14: =IF(B14="","",DATE(YEAR(B14),MONTH(B14),1))
B15: 46279 | C15: Grocery run | D15: Expense | E15: Groceries | F15: 142.75 | G15: Credit card | H15: example | I15: =IF(B15="","",DATE(YEAR(B15),MONTH(B15),1))
B16: 46280 | C16: Paycheck | D16: Income | E16: Salary | F16: 3200 | G16: Checking | H16: example | I16: =IF(B16="","",DATE(YEAR(B16),MONTH(B16),1))
B17: 46281 | C17: Phone plan | D17: Expense | E17: Phone & internet | F17: 70 | G17: Checking | H17: example | I17: =IF(B17="","",DATE(YEAR(B17),MONTH(B17),1))
B18: 46283 | C18: Transfer to savings | D18: Expense | E18: Savings transfers | F18: 400 | G18: Savings | H18: example | I18: =IF(B18="","",DATE(YEAR(B18),MONTH(B18),1))
... B35: 46295 | C35: Credit card payment | D35: Expense | E35: Debt payments | F35: 250 | G35: Checking | H35: example | I35: =IF(B35="","",DATE(YEAR(B35),MONTH(B35),1))
I36: =IF(B36="","",DATE(YEAR(B36),MONTH(B36),1))
I37: =IF(B37="","",DATE(YEAR(B37),MONTH(B37),1))
I38: =IF(B38="","",DATE(YEAR(B38),MONTH(B38),1))
I39: =IF(B39="","",DATE(YEAR(B39),MONTH(B39),1))
I40: =IF(B40="","",DATE(YEAR(B40),MONTH(B40),1))
I41: =IF(B41="","",DATE(YEAR(B41),MONTH(B41),1))
I42: =IF(B42="","",DATE(YEAR(B42),MONTH(B42),1))
I43: =IF(B43="","",DATE(YEAR(B43),MONTH(B43),1))
I44: =IF(B44="","",DATE(YEAR(B44),MONTH(B44),1))
I45: =IF(B45="","",DATE(YEAR(B45),MONTH(B45),1))
I46: =IF(B46="","",DATE(YEAR(B46),MONTH(B46),1))
I47: =IF(B47="","",DATE(YEAR(B47),MONTH(B47),1))
... I1006: =IF(B1006="","",DATE(YEAR(B1006),MONTH(B1006),1))

Sheet Budget Plan
B2: Budget Plan
B3: Type a default monthly amount per category. Every month copies the default — overwrite any single month to change it.
B6: Category | C6: Default / month | D6: =Settings!$H$8 | E6: =Settings!$H$9 | F6: =Settings!$H$10 | G6: =Settings!$H$11 | H6: =Settings!$H$12 | I6: =Settings!$H$13 | J6: =Settings!$H$14 | K6: =Settings!$H$15 | L6: =Settings!$H$16 | M6: =Settings!$H$17 | N6: =Settings!$H$18 | O6: =Settings!$H$19
B7: INCOME
B8: =IF(Settings!D8="","",Settings!D8) | C8: 6400 | D8: =$C8 | E8: =$C8 | F8: =$C8 | G8: =$C8 | H8: =$C8 | I8: =$C8 | J8: =$C8 | K8: =$C8 | ... O8: =$C8
B9: =IF(Settings!D9="","",Settings!D9) | D9: =$C9 | E9: =$C9 | F9: =$C9 | G9: =$C9 | H9: =$C9 | I9: =$C9 | J9: =$C9 | K9: =$C9 | ... O9: =$C9
B10: =IF(Settings!D10="","",Settings!D10) | C10: 450 | D10: =$C10 | E10: =$C10 | F10: =$C10 | G10: =$C10 | H10: =$C10 | I10: =$C10 | J10: =$C10 | K10: =$C10 | ... O10: =$C10
B11: =IF(Settings!D11="","",Settings!D11) | D11: =$C11 | E11: =$C11 | F11: =$C11 | G11: =$C11 | H11: =$C11 | I11: =$C11 | J11: =$C11 | K11: =$C11 | ... O11: =$C11
B12: =IF(Settings!D12="","",Settings!D12) | D12: =$C12 | E12: =$C12 | F12: =$C12 | G12: =$C12 | H12: =$C12 | I12: =$C12 | J12: =$C12 | K12: =$C12 | ... O12: =$C12
B13: =IF(Settings!D13="","",Settings!D13) | D13: =$C13 | E13: =$C13 | F13: =$C13 | G13: =$C13 | H13: =$C13 | I13: =$C13 | J13: =$C13 | K13: =$C13 | ... O13: =$C13
B14: =IF(Settings!D14="","",Settings!D14) | D14: =$C14 | E14: =$C14 | F14: =$C14 | G14: =$C14 | H14: =$C14 | I14: =$C14 | J14: =$C14 | K14: =$C14 | ... O14: =$C14
B15: =IF(Settings!D15="","",Settings!D15) | D15: =$C15 | E15: =$C15 | F15: =$C15 | G15: =$C15 | H15: =$C15 | I15: =$C15 | J15: =$C15 | K15: =$C15 | ... O15: =$C15
B16: =IF(Settings!D16="","",Settings!D16) | D16: =$C16 | E16: =$C16 | F16: =$C16 | G16: =$C16 | H16: =$C16 | I16: =$C16 | J16: =$C16 | K16: =$C16 | ... O16: =$C16
B17: =IF(Settings!D17="","",Settings!D17) | D17: =$C17 | E17: =$C17 | F17: =$C17 | G17: =$C17 | H17: =$C17 | I17: =$C17 | J17: =$C17 | K17: =$C17 | ... O17: =$C17
B18: Total planned income | C18: =SUM(C8:C17) | D18: =SUM(D8:D17) | E18: =SUM(E8:E17) | F18: =SUM(F8:F17) | G18: =SUM(G8:G17) | H18: =SUM(H8:H17) | I18: =SUM(I8:I17) | J18: =SUM(J8:J17) | ... O18: =SUM(O8:O17)
B20: EXPENSES
B21: =IF(Settings!B8="","",Settings!B8) | C21: 1450 | D21: =$C21 | E21: =$C21 | F21: =$C21 | G21: =$C21 | H21: =$C21 | I21: =$C21 | J21: =$C21 | K21: =$C21 | ... O21: =$C21
B22: =IF(Settings!B9="","",Settings!B9) | C22: 120 | D22: =$C22 | E22: =$C22 | F22: =$C22 | G22: =$C22 | H22: =$C22 | I22: =$C22 | J22: =$C22 | K22: =$C22 | ... O22: =$C22
B23: =IF(Settings!B10="","",Settings!B10) | C23: 550 | D23: =$C23 | E23: =$C23 | F23: =$C23 | G23: =$C23 | H23: =$C23 | I23: =$C23 | J23: =$C23 | K23: =$C23 | ... O23: =$C23
B24: =IF(Settings!B11="","",Settings!B11) | C24: 200 | D24: =$C24 | E24: =$C24 | F24: =$C24 | G24: =$C24 | H24: =$C24 | I24: =$C24 | J24: =$C24 | K24: =$C24 | ... O24: =$C24
B25: =IF(Settings!B12="","",Settings!B12) | C25: 220 | D25: =$C25 | E25: =$C25 | F25: =$C25 | G25: =$C25 | H25: =$C25 | I25: =$C25 | J25: =$C25 | K25: =$C25 | ... O25: =$C25
B26: =IF(Settings!B13="","",Settings!B13) | C26: 130 | D26: =$C26 | E26: =$C26 | F26: =$C26 | G26: =$C26 | H26: =$C26 | I26: =$C26 | J26: =$C26 | K26: =$C26 | ... O26: =$C26
B27: =IF(Settings!B14="","",Settings!B14) | C27: 60 | D27: =$C27 | E27: =$C27 | F27: =$C27 | G27: =$C27 | H27: =$C27 | I27: =$C27 | J27: =$C27 | K27: =$C27 | ... O27: =$C27
B28: =IF(Settings!B15="","",Settings!B15) | C28: 45 | D28: =$C28 | E28: =$C28 | F28: =$C28 | G28: =$C28 | H28: =$C28 | I28: =$C28 | J28: =$C28 | K28: =$C28 | ... O28: =$C28
B29: =IF(Settings!B16="","",Settings!B16) | C29: 90 | D29: =$C29 | E29: =$C29 | F29: =$C29 | G29: =$C29 | H29: =$C29 | I29: =$C29 | J29: =$C29 | K29: =$C29 | ... O29: =$C29
B30: =IF(Settings!B17="","",Settings!B17) | C30: 150 | D30: =$C30 | E30: =$C30 | F30: =$C30 | G30: =$C30 | H30: =$C30 | I30: =$C30 | J30: =$C30 | K30: =$C30 | ... O30: =$C30
B31: =IF(Settings!B18="","",Settings!B18) | C31: 40 | D31: =$C31 | E31: =$C31 | F31: =$C31 | G31: =$C31 | H31: =$C31 | I31: =$C31 | J31: =$C31 | K31: =$C31 | ... O31: =$C31
B32: =IF(Settings!B19="","",Settings!B19) | D32: =$C32 | E32: =$C32 | F32: =$C32 | G32: =$C32 | H32: =$C32 | I32: =$C32 | J32: =$C32 | K32: =$C32 | ... O32: =$C32
B33: =IF(Settings!B20="","",Settings!B20) | D33: =$C33 | E33: =$C33 | F33: =$C33 | G33: =$C33 | H33: =$C33 | I33: =$C33 | J33: =$C33 | K33: =$C33 | ... O33: =$C33
B34: =IF(Settings!B21="","",Settings!B21) | C34: 50 | D34: =$C34 | E34: =$C34 | F34: =$C34 | G34: =$C34 | H34: =$C34 | I34: =$C34 | J34: =$C34 | K34: =$C34 | ... O34: =$C34
B35: =IF(Settings!B22="","",Settings!B22) | C35: 120 | D35: =$C35 | E35: =$C35 | F35: =$C35 | G35: =$C35 | H35: =$C35 | I35: =$C35 | J35: =$C35 | K35: =$C35 | ... O35: =$C35
B36: =IF(Settings!B23="","",Settings!B23) | C36: 150 | D36: =$C36 | E36: =$C36 | F36: =$C36 | G36: =$C36 | H36: =$C36 | I36: =$C36 | J36: =$C36 | K36: =$C36 | ... O36: =$C36
B37: =IF(Settings!B24="","",Settings!B24) | D37: =$C37 | E37: =$C37 | F37: =$C37 | G37: =$C37 | H37: =$C37 | I37: =$C37 | J37: =$C37 | K37: =$C37 | ... O37: =$C37
B38: =IF(Settings!B25="","",Settings!B25) | D38: =$C38 | E38: =$C38 | F38: =$C38 | G38: =$C38 | H38: =$C38 | I38: =$C38 | J38: =$C38 | K38: =$C38 | ... O38: =$C38
B39: =IF(Settings!B26="","",Settings!B26) | C39: 800 | D39: =$C39 | E39: =$C39 | F39: =$C39 | G39: =$C39 | H39: =$C39 | I39: =$C39 | J39: =$C39 | K39: =$C39 | ... O39: =$C39
B40: =IF(Settings!B27="","",Settings!B27) | C40: 75 | D40: =$C40 | E40: =$C40 | F40: =$C40 | G40: =$C40 | H40: =$C40 | I40: =$C40 | J40: =$C40 | K40: =$C40 | ... O40: =$C40
B41: =IF(Settings!B28="","",Settings!B28) | D41: =$C41 | E41: =$C41 | F41: =$C41 | G41: =$C41 | H41: =$C41 | I41: =$C41 | J41: =$C41 | K41: =$C41 | ... O41: =$C41
B42: =IF(Settings!B29="","",Settings!B29) | D42: =$C42 | E42: =$C42 | F42: =$C42 | G42: =$C42 | H42: =$C42 | I42: =$C42 | J42: =$C42 | K42: =$C42 | ... O42: =$C42
B43: =IF(Settings!B30="","",Settings!B30) | D43: =$C43 | E43: =$C43 | F43: =$C43 | G43: =$C43 | H43: =$C43 | I43: =$C43 | J43: =$C43 | K43: =$C43 | ... O43: =$C43
B44: =IF(Settings!B31="","",Settings!B31) | D44: =$C44 | E44: =$C44 | F44: =$C44 | G44: =$C44 | H44: =$C44 | I44: =$C44 | J44: =$C44 | K44: =$C44 | ... O44: =$C44
...

Sheet Annual Overview
B2: Annual Overview
B3: Actual spending per category, every month of the year. Fully automatic.
B6: Category | C6: =Settings!$H$8 | D6: =Settings!$H$9 | E6: =Settings!$H$10 | F6: =Settings!$H$11 | G6: =Settings!$H$12 | H6: =Settings!$H$13 | I6: =Settings!$H$14 | J6: =Settings!$H$15 | K6: =Settings!$H$16 | L6: =Settings!$H$17 | M6: =Settings!$H$18 | N6: =Settings!$H$19 | O6: Year total | P6: Monthly avg
B7: INCOME
B8: =IF(Settings!D8="","",Settings!D8) | C8: =IF($B8="","",SUMIFS(Transactions!$F$7:$F$1006,Transactions!$D$7:$D$1006,"Income",Transactions!$E$7:$E$1006,$B8,Transactions!$I$7:$I$1006,C$6)) | D8: =IF($B8="","",SUMIFS(Transactions!$F$7:$F$1006,Transactions!$D$7:$D$1006,"Income",Transactions!$E$7:$E$1006,$B8,Transactions!$I$7:$I$1006,D$6)) | E8: =IF($B8="","",SUMIFS(Transactions!$F$7:$F$1006,Transactions!$D$7:$D$1006,"Income",Transactions!$E$7:$E$1006,$B8,Transactions!$I$7:$I$1006,E$6)) | F8: =IF($B8="","",SUMIFS(Transactions!$F$7:$F$1006,Transactions!$D$7:$D$1006,"Income",Transactions!$E$7:$E$1006,$B8,Transactions!$I$7:$I$1006,F$6)) | G8: =IF($B8="","",SUMIFS(Transactions!$F$7:$F$1006,Transactions!$D$7:$D$1006,"Income",Transactions!$E$7:$E$1006,$B8,Transactions!$I$7:$I$1006,G$6)) | H8: =IF($B8="","",SUMIFS(Transactions!$F$7:$F$1006,Transactions!$D$7:$D$1006,"Income",Transactions!$E$7:$E$1006,$B8,Transactions!$I$7:$I$1006,H$6)) | I8: =IF($B8="","",SUMIFS(Transactions!$F$7:$F$1006,Transactions!$D$7:$D$1006,"Income",Transactions!$E$7:$E$1006,$B8,Transactions!$I$7:$I$1006,I$6)) | J8: =IF($B8="","",SUMIFS(Transactions!$F$7:$F$1006,Transactions!$D$7:$D$1006,"Income",Transactions!$E$7:$E$1006,$B8,Transactions!$I$7:$I$1006,J$6)) | ... N8: =IF($B8="","",SUMIFS(Transactions!$F$7:$F$1006,Transactions!$D$7:$D$1006,"Income",Transactions!$E$7:$E$1006,$B8,Transactions!$I$7:$I$1006,N$6)) | O8: =IF($B8="","",SUM(C8:N8)) | P8: =IF($B8="","",IFERROR(O8/MAX(1,COUNTIF(C8:N8,">0")),0))
B9: =IF(Settings!D9="","",Settings!D9) | C9: =IF($B9="","",SUMIFS(Transactions!$F$7:$F$1006,Transactions!$D$7:$D$1006,"Income",Transactions!$E$7:$E$1006,$B9,Transactions!$I$7:$I$1006,C$6)) | D9: =IF($B9="","",SUMIFS(Transactions!$F$7:$F$1006,Transactions!$D$7:$D$1006,"Income",Transactions!$E$7:$E$1006,$B9,Transactions!$I$7:$I$1006,D$6)) | E9: =IF($B9="","",SUMIFS(Transactions!$F$7:$F$1006,Transactions!$D$7:$D$1006,"Income",Transactions!$E$7:$E$1006,$B9,Transactions!$I$7:$I$1006,E$6)) | F9: =IF($B9="","",SUMIFS(Transactions!$F$7:$F$1006,Transactions!$D$7:$D$1006,"Income",Transactions!$E$7:$E$1006,$B9,Transactions!$I$7:$I$1006,F$6)) | G9: =IF($B9="","",SUMIFS(Transactions!$F$7:$F$1006,Transactions!$D$7:$D$1006,"Income",Transactions!$E$7:$E$1006,$B9,Transactions!$I$7:$I$1006,G$6)) | H9: =IF($B9="","",SUMIFS(Transactions!$F$7:$F$1006,Transactions!$D$7:$D$1006,"Income",Transactions!$E$7:$E$1006,$B9,Transactions!$I$7:$I$1006,H$6)) | I9: =IF($B9="","",SUMIFS(Transactions!$F$7:$F$1006,Transactions!$D$7:$D$1006,"Income",Transactions!$E$7:$E$1006,$B9,Transactions!$I$7:$I$1006,I$6)) | J9: =IF($B9="","",SUMIFS(Transactions!$F$7:$F$1006,Transactions!$D$7:$D$1006,"Income",Transactions!$E$7:$E$1006,$B9,Transactions!$I$7:$I$1006,J$6)) | ... N9: =IF($B9="","",SUMIFS(Transactions!$F$7:$F$1006,Transactions!$D$7:$D$1006,"Income",Transactions!$E$7:$E$1006,$B9,Transactions!$I$7:$I$1006,N$6)) | O9: =IF($B9="","",SUM(C9:N9)) | P9: =IF($B9="","",IFERROR(O9/MAX(1,COUNTIF(C9:N9,">0")),0))
B10: =IF(Settings!D10="","",Settings!D10) | C10: =IF($B10="","",SUMIFS(Transactions!$F$7:$F$1006,Transactions!$D$7:$D$1006,"Income",Transactions!$E$7:$E$1006,$B10,Transactions!$I$7:$I$1006,C$6)) | D10: =IF($B10="","",SUMIFS(Transactions!$F$7:$F$1006,Transactions!$D$7:$D$1006,"Income",Transactions!$E$7:$E$1006,$B10,Transactions!$I$7:$I$1006,D$6)) | E10: =IF($B10="","",SUMIFS(Transactions!$F$7:$F$1006,Transactions!$D$7:$D$1006,"Income",Transactions!$E$7:$E$1006,$B10,Transactions!$I$7:$I$1006,E$6)) | F10: =IF($B10="","",SUMIFS(Transactions!$F$7:$F$1006,Transactions!$D$7:$D$1006,"Income",Transactions!$E$7:$E$1006,$B10,Transactions!$I$7:$I$1006,F$6)) | G10: =IF($B10="","",SUMIFS(Transactions!$F$7:$F$1006,Transactions!$D$7:$D$1006,"Income",Transactions!$E$7:$E$1006,$B10,Transactions!$I$7:$I$1006,G$6)) | H10: =IF($B10="","",SUMIFS(Transactions!$F$7:$F$1006,Transactions!$D$7:$D$1006,"Income",Transactions!$E$7:$E$1006,$B10,Transactions!$I$7:$I$1006,H$6)) | I10: =IF($B10="","",SUMIFS(Transactions!$F$7:$F$1006,Transactions!$D$7:$D$1006,"Income",Transactions!$E$7:$E$1006,$B10,Transactions!$I$7:$I$1006,I$6)) | J10: =IF($B10="","",SUMIFS(Transactions!$F$7:$F$1006,Transactions!$D$7:$D$1006,"Income",Transactions!$E$7:$E$1006,$B10,Transactions!$I$7:$I$1006,J$6)) | ... N10: =IF($B10="","",SUMIFS(Transactions!$F$7:$F$1006,Transactions!$D$7:$D$1006,"Income",Transactions!$E$7:$E$1006,$B10,Transactions!$I$7:$I$1006,N$6)) | O10: =IF($B10="","",SUM(C10:N10)) | P10: =IF($B10="","",IFERROR(O10/MAX(1,COUNTIF(C10:N10,">0")),0))
B11: =IF(Settings!D11="","",Settings!D11) | C11: =IF($B11="","",SUMIFS(Transactions!$F$7:$F$1006,Transactions!$D$7:$D$1006,"Income",Transactions!$E$7:$E$1006,$B11,Transactions!$I$7:$I$1006,C$6)) | D11: =IF($B11="","",SUMIFS(Transactions!$F$7:$F$1006,Transactions!$D$7:$D$1006,"Income",Transactions!$E$7:$E$1006,$B11,Transactions!$I$7:$I$1006,D$6)) | E11: =IF($B11="","",SUMIFS(Transactions!$F$7:$F$1006,Transactions!$D$7:$D$1006,"Income",Transactions!$E$7:$E$1006,$B11,Transactions!$I$7:$I$1006,E$6)) | F11: =IF($B11="","",SUMIFS(Transactions!$F$7:$F$1006,Transactions!$D$7:$D$1006,"Income",Transactions!$E$7:$E$1006,$B11,Transactions!$I$7:$I$1006,F$6)) | G11: =IF($B11="","",SUMIFS(Transactions!$F$7:$F$1006,Transactions!$D$7:$D$1006,"Income",Transactions!$E$7:$E$1006,$B11,Transactions!$I$7:$I$1006,G$6)) | H11: =IF($B11="","",SUMIFS(Transactions!$F$7:$F$1006,Transactions!$D$7:$D$1006,"Income",Transactions!$E$7:$E$1006,$B11,Transactions!$I$7:$I$1006,H$6)) | I11: =IF($B11="","",SUMIFS(Transactions!$F$7:$F$1006,Transactions!$D$7:$D$1006,"Income",Transactions!$E$7:$E$1006,$B11,Transactions!$I$7:$I$1006,I$6)) | J11: =IF($B11="","",SUMIFS(Transactions!$F$7:$F$1006,Transactions!$D$7:$D$1006,"Income",Transactions!$E$7:$E$1006,$B11,Transactions!$I$7:$I$1006,J$6)) | ... N11: =IF($B11="","",SUMIFS(Transactions!$F$7:$F$1006,Transactions!$D$7:$D$1006,"Income",Transactions!$E$7:$E$1006,$B11,Transactions!$I$7:$I$1006,N$6)) | O11: =IF($B11="","",SUM(C11:N11)) | P11: =IF($B11="","",IFERROR(O11/MAX(1,COUNTIF(C11:N11,">0")),0))
B12: =IF(Settings!D12="","",Settings!D12) | C12: =IF($B12="","",SUMIFS(Transactions!$F$7:$F$1006,Transactions!$D$7:$D$1006,"Income",Transactions!$E$7:$E$1006,$B12,Transactions!$I$7:$I$1006,C$6)) | D12: =IF($B12="","",SUMIFS(Transactions!$F$7:$F$1006,Transactions!$D$7:$D$1006,"Income",Transactions!$E$7:$E$1006,$B12,Transactions!$I$7:$I$1006,D$6)) | E12: =IF($B12="","",SUMIFS(Transactions!$F$7:$F$1006,Transactions!$D$7:$D$1006,"Income",Transactions!$E$7:$E$1006,$B12,Transactions!$I$7:$I$1006,E$6)) | F12: =IF($B12="","",SUMIFS(Transactions!$F$7:$F$1006,Transactions!$D$7:$D$1006,"Income",Transactions!$E$7:$E$1006,$B12,Transactions!$I$7:$I$1006,F$6)) | G12: =IF($B12="","",SUMIFS(Transactions!$F$7:$F$1006,Transactions!$D$7:$D$1006,"Income",Transactions!$E$7:$E$1006,$B12,Transactions!$I$7:$I$1006,G$6)) | H12: =IF($B12="","",SUMIFS(Transactions!$F$7:$F$1006,Transactions!$D$7:$D$1006,"Income",Transactions!$E$7:$E$1006,$B12,Transactions!$I$7:$I$1006,H$6)) | I12: =IF($B12="","",SUMIFS(Transactions!$F$7:$F$1006,Transactions!$D$7:$D$1006,"Income",Transactions!$E$7:$E$1006,$B12,Transactions!$I$7:$I$1006,I$6)) | J12: =IF($B12="","",SUMIFS(Transactions!$F$7:$F$1006,Transactions!$D$7:$D$1006,"Income",Transactions!$E$7:$E$1006,$B12,Transactions!$I$7:$I$1006,J$6)) | ... N12: =IF($B12="","",SUMIFS(Transactions!$F$7:$F$1006,Transactions!$D$7:$D$1006,"Income",Transactions!$E$7:$E$1006,$B12,Transactions!$I$7:$I$1006,N$6)) | O12: =IF($B12="","",SUM(C12:N12)) | P12: =IF($B12="","",IFERROR(O12/MAX(1,COUNTIF(C12:N12,">0")),0))
B13: =IF(Settings!D13="","",Settings!D13) | C13: =IF($B13="","",SUMIFS(Transactions!$F$7:$F$1006,Transactions!$D$7:$D$1006,"Income",Transactions!$E$7:$E$1006,$B13,Transactions!$I$7:$I$1006,C$6)) | D13: =IF($B13="","",SUMIFS(Transactions!$F$7:$F$1006,Transactions!$D$7:$D$1006,"Income",Transactions!$E$7:$E$1006,$B13,Transactions!$I$7:$I$1006,D$6)) | E13: =IF($B13="","",SUMIFS(Transactions!$F$7:$F$1006,Transactions!$D$7:$D$1006,"Income",Transactions!$E$7:$E$1006,$B13,Transactions!$I$7:$I$1006,E$6)) | F13: =IF($B13="","",SUMIFS(Transactions!$F$7:$F$1006,Transactions!$D$7:$D$1006,"Income",Transactions!$E$7:$E$1006,$B13,Transactions!$I$7:$I$1006,F$6)) | G13: =IF($B13="","",SUMIFS(Transactions!$F$7:$F$1006,Transactions!$D$7:$D$1006,"Income",Transactions!$E$7:$E$1006,$B13,Transactions!$I$7:$I$1006,G$6)) | H13: =IF($B13="","",SUMIFS(Transactions!$F$7:$F$1006,Transactions!$D$7:$D$1006,"Income",Transactions!$E$7:$E$1006,$B13,Transactions!$I$7:$I$1006,H$6)) | I13: =IF($B13="","",SUMIFS(Transactions!$F$7:$F$1006,Transactions!$D$7:$D$1006,"Income",Transactions!$E$7:$E$1006,$B13,Transactions!$I$7:$I$1006,I$6)) | J13: =IF($B13="","",SUMIFS(Transactions!$F$7:$F$1006,Transactions!$D$7:$D$1006,"Income",Transactions!$E$7:$E$1006,$B13,Transactions!$I$7:$I$1006,J$6)) | ... N13: =IF($B13="","",SUMIFS(Transactions!$F$7:$F$1006,Transactions!$D$7:$D$1006,"Income",Transactions!$E$7:$E$1006,$B13,Transactions!$I$7:$I$1006,N$6)) | O13: =IF($B13="","",SUM(C13:N13)) | P13: =IF($B13="","",IFERROR(O13/MAX(1,COUNTIF(C13:N13,">0")),0))
B14: =IF(Settings!D14="","",Settings!D14) | C14: =IF($B14="","",SUMIFS(Transactions!$F$7:$F$1006,Transactions!$D$7:$D$1006,"Income",Transactions!$E$7:$E$1006,$B14,Transactions!$I$7:$I$1006,C$6)) | D14: =IF($B14="","",SUMIFS(Transactions!$F$7:$F$1006,Transactions!$D$7:$D$1006,"Income",Transactions!$E$7:$E$1006,$B14,Transactions!$I$7:$I$1006,D$6)) | E14: =IF($B14="","",SUMIFS(Transactions!$F$7:$F$1006,Transactions!$D$7:$D$1006,"Income",Transactions!$E$7:$E$1006,$B14,Transactions!$I$7:$I$1006,E$6)) | F14: =IF($B14="","",SUMIFS(Transactions!$F$7:$F$1006,Transactions!$D$7:$D$1006,"Income",Transactions!$E$7:$E$1006,$B14,Transactions!$I$7:$I$1006,F$6)) | G14: =IF($B14="","",SUMIFS(Transactions!$F$7:$F$1006,Transactions!$D$7:$D$1006,"Income",Transactions!$E$7:$E$1006,$B14,Transactions!$I$7:$I$1006,G$6)) | H14: =IF($B14="","",SUMIFS(Transactions!$F$7:$F$1006,Transactions!$D$7:$D$1006,"Income",Transactions!$E$7:$E$1006,$B14,Transactions!$I$7:$I$1006,H$6)) | I14: =IF($B14="","",SUMIFS(Transactions!$F$7:$F$1006,Transactions!$D$7:$D$1006,"Income",Transactions!$E$7:$E$1006,$B14,Transactions!$I$7:$I$1006,I$6)) | J14: =IF($B14="","",SUMIFS(Transactions!$F$7:$F$1006,Transactions!$D$7:$D$1006,"Income",Transactions!$E$7:$E$1006,$B14,Transactions!$I$7:$I$1006,J$6)) | ... N14: =IF($B14="","",SUMIFS(Transactions!$F$7:$F$1006,Transactions!$D$7:$D$1006,"Income",Transactions!$E$7:$E$1006,$B14,Transactions!$I$7:$I$1006,N$6)) | O14: =IF($B14="","",SUM(C14:N14)) | P14: =IF($B14="","",IFERROR(O14/MAX(1,COUNTIF(C14:N14,">0")),0))
B15: =IF(Settings!D15="","",Settings!D15) | C15: =IF($B15="","",SUMIFS(Transactions!$F$7:$F$1006,Transactions!$D$7:$D$1006,"Income",Transactions!$E$7:$E$1006,$B15,Transactions!$I$7:$I$1006,C$6)) | D15: =IF($B15="","",SUMIFS(Transactions!$F$7:$F$1006,Transactions!$D$7:$D$1006,"Income",Transactions!$E$7:$E$1006,$B15,Transactions!$I$7:$I$1006,D$6)) | E15: =IF($B15="","",SUMIFS(Transactions!$F$7:$F$1006,Transactions!$D$7:$D$1006,"Income",Transactions!$E$7:$E$1006,$B15,Transactions!$I$7:$I$1006,E$6)) | F15: =IF($B15="","",SUMIFS(Transactions!$F$7:$F$1006,Transactions!$D$7:$D$1006,"Income",Transactions!$E$7:$E$1006,$B15,Transactions!$I$7:$I$1006,F$6)) | G15: =IF($B15="","",SUMIFS(Transactions!$F$7:$F$1006,Transactions!$D$7:$D$1006,"Income",Transactions!$E$7:$E$1006,$B15,Transactions!$I$7:$I$1006,G$6)) | H15: =IF($B15="","",SUMIFS(Transactions!$F$7:$F$1006,Transactions!$D$7:$D$1006,"Income",Transactions!$E$7:$E$1006,$B15,Transactions!$I$7:$I$1006,H$6)) | I15: =IF($B15="","",SUMIFS(Transactions!$F$7:$F$1006,Transactions!$D$7:$D$1006,"Income",Transactions!$E$7:$E$1006,$B15,Transactions!$I$7:$I$1006,I$6)) | J15: =IF($B15="","",SUMIFS(Transactions!$F$7:$F$1006,Transactions!$D$7:$D$1006,"Income",Transactions!$E$7:$E$1006,$B15,Transactions!$I$7:$I$1006,J$6)) | ... N15: =IF($B15="","",SUMIFS(Transactions!$F$7:$F$1006,Transactions!$D$7:$D$1006,"Income",Transactions!$E$7:$E$1006,$B15,Transactions!$I$7:$I$1006,N$6)) | O15: =IF($B15="","",SUM(C15:N15)) | P15: =IF($B15="","",IFERROR(O15/MAX(1,COUNTIF(C15:N15,">0")),0))
B16: =IF(Settings!D16="","",Settings!D16) | C16: =IF($B16="","",SUMIFS(Transactions!$F$7:$F$1006,Transactions!$D$7:$D$1006,"Income",Transactions!$E$7:$E$1006,$B16,Transactions!$I$7:$I$1006,C$6)) | D16: =IF($B16="","",SUMIFS(Transactions!$F$7:$F$1006,Transactions!$D$7:$D$1006,"Income",Transactions!$E$7:$E$1006,$B16,Transactions!$I$7:$I$1006,D$6)) | E16: =IF($B16="","",SUMIFS(Transactions!$F$7:$F$1006,Transactions!$D$7:$D$1006,"Income",Transactions!$E$7:$E$1006,$B16,Transactions!$I$7:$I$1006,E$6)) | F16: =IF($B16="","",SUMIFS(Transactions!$F$7:$F$1006,Transactions!$D$7:$D$1006,"Income",Transactions!$E$7:$E$1006,$B16,Transactions!$I$7:$I$1006,F$6)) | G16: =IF($B16="","",SUMIFS(Transactions!$F$7:$F$1006,Transactions!$D$7:$D$1006,"Income",Transactions!$E$7:$E$1006,$B16,Transactions!$I$7:$I$1006,G$6)) | H16: =IF($B16="","",SUMIFS(Transactions!$F$7:$F$1006,Transactions!$D$7:$D$1006,"Income",Transactions!$E$7:$E$1006,$B16,Transactions!$I$7:$I$1006,H$6)) | I16: =IF($B16="","",SUMIFS(Transactions!$F$7:$F$1006,Transactions!$D$7:$D$1006,"Income",Transactions!$E$7:$E$1006,$B16,Transactions!$I$7:$I$1006,I$6)) | J16: =IF($B16="","",SUMIFS(Transactions!$F$7:$F$1006,Transactions!$D$7:$D$1006,"Income",Transactions!$E$7:$E$1006,$B16,Transactions!$I$7:$I$1006,J$6)) | ... N16: =IF($B16="","",SUMIFS(Transactions!$F$7:$F$1006,Transactions!$D$7:$D$1006,"Income",Transactions!$E$7:$E$1006,$B16,Transactions!$I$7:$I$1006,N$6)) | O16: =IF($B16="","",SUM(C16:N16)) | P16: =IF($B16="","",IFERROR(O16/MAX(1,COUNTIF(C16:N16,">0")),0))
B17: =IF(Settings!D17="","",Settings!D17) | C17: =IF($B17="","",SUMIFS(Transactions!$F$7:$F$1006,Transactions!$D$7:$D$1006,"Income",Transactions!$E$7:$E$1006,$B17,Transactions!$I$7:$I$1006,C$6)) | D17: =IF($B17="","",SUMIFS(Transactions!$F$7:$F$1006,Transactions!$D$7:$D$1006,"Income",Transactions!$E$7:$E$1006,$B17,Transactions!$I$7:$I$1006,D$6)) | E17: =IF($B17="","",SUMIFS(Transactions!$F$7:$F$1006,Transactions!$D$7:$D$1006,"Income",Transactions!$E$7:$E$1006,$B17,Transactions!$I$7:$I$1006,E$6)) | F17: =IF($B17="","",SUMIFS(Transactions!$F$7:$F$1006,Transactions!$D$7:$D$1006,"Income",Transactions!$E$7:$E$1006,$B17,Transactions!$I$7:$I$1006,F$6)) | G17: =IF($B17="","",SUMIFS(Transactions!$F$7:$F$1006,Transactions!$D$7:$D$1006,"Income",Transactions!$E$7:$E$1006,$B17,Transactions!$I$7:$I$1006,G$6)) | H17: =IF($B17="","",SUMIFS(Transactions!$F$7:$F$1006,Transactions!$D$7:$D$1006,"Income",Transactions!$E$7:$E$1006,$B17,Transactions!$I$7:$I$1006,H$6)) | I17: =IF($B17="","",SUMIFS(Transactions!$F$7:$F$1006,Transactions!$D$7:$D$1006,"Income",Transactions!$E$7:$E$1006,$B17,Transactions!$I$7:$I$1006,I$6)) | J17: =IF($B17="","",SUMIFS(Transactions!$F$7:$F$1006,Transactions!$D$7:$D$1006,"Income",Transactions!$E$7:$E$1006,$B17,Transactions!$I$7:$I$1006,J$6)) | ... N17: =IF($B17="","",SUMIFS(Transactions!$F$7:$F$1006,Transactions!$D$7:$D$1006,"Income",Transactions!$E$7:$E$1006,$B17,Transactions!$I$7:$I$1006,N$6)) | O17: =IF($B17="","",SUM(C17:N17)) | P17: =IF($B17="","",IFERROR(O17/MAX(1,COUNTIF(C17:N17,">0")),0))
B18: Total income | C18: =SUM(C8:C17) | D18: =SUM(D8:D17) | E18: =SUM(E8:E17) | F18: =SUM(F8:F17) | G18: =SUM(G8:G17) | H18: =SUM(H8:H17) | I18: =SUM(I8:I17) | J18: =SUM(J8:J17) | ... P18: =SUM(P8:P17)
B20: EXPENSES
B21: =IF(Settings!B8="","",Settings!B8) | C21: =IF($B21="","",SUMIFS(Transactions!$F$7:$F$1006,Transactions!$D$7:$D$1006,"Expense",Transactions!$E$7:$E$1006,$B21,Transactions!$I$7:$I$1006,C$6)) | D21: =IF($B21="","",SUMIFS(Transactions!$F$7:$F$1006,Transactions!$D$7:$D$1006,"Expense",Transactions!$E$7:$E$1006,$B21,Transactions!$I$7:$I$1006,D$6)) | E21: =IF($B21="","",SUMIFS(Transactions!$F$7:$F$1006,Transactions!$D$7:$D$1006,"Expense",Transactions!$E$7:$E$1006,$B21,Transactions!$I$7:$I$1006,E$6)) | F21: =IF($B21="","",SUMIFS(Transactions!$F$7:$F$1006,Transactions!$D$7:$D$1006,"Expense",Transactions!$E$7:$E$1006,$B21,Transactions!$I$7:$I$1006,F$6)) | G21: =IF($B21="","",SUMIFS(Transactions!$F$7:$F$1006,Transactions!$D$7:$D$1006,"Expense",Transactions!$E$7:$E$1006,$B21,Transactions!$I$7:$I$1006,G$6)) | H21: =IF($B21="","",SUMIFS(Transactions!$F$7:$F$1006,Transactions!$D$7:$D$1006,"Expense",Transactions!$E$7:$E$1006,$B21,Transactions!$I$7:$I$1006,H$6)) | I21: =IF($B21="","",SUMIFS(Transactions!$F$7:$F$1006,Transactions!$D$7:$D$1006,"Expense",Transactions!$E$7:$E$1006,$B21,Transactions!$I$7:$I$1006,I$6)) | J21: =IF($B21="","",SUMIFS(Transactions!$F$7:$F$1006,Transactions!$D$7:$D$1006,"Expense",Transactions!$E$7:$E$1006,$B21,Transactions!$I$7:$I$1006,J$6)) | ... N21: =IF($B21="","",SUMIFS(Transactions!$F$7:$F$1006,Transactions!$D$7:$D$1006,"Expense",Transactions!$E$7:$E$1006,$B21,Transactions!$I$7:$I$1006,N$6)) | O21: =IF($B21="","",SUM(C21:N21)) | P21: =IF($B21="","",IFERROR(O21/MAX(1,COUNTIF(C21:N21,">0")),0))
B22: =IF(Settings!B9="","",Settings!B9) | C22: =IF($B22="","",SUMIFS(Transactions!$F$7:$F$1006,Transactions!$D$7:$D$1006,"Expense",Transactions!$E$7:$E$1006,$B22,Transactions!$I$7:$I$1006,C$6)) | D22: =IF($B22="","",SUMIFS(Transactions!$F$7:$F$1006,Transactions!$D$7:$D$1006,"Expense",Transactions!$E$7:$E$1006,$B22,Transactions!$I$7:$I$1006,D$6)) | E22: =IF($B22="","",SUMIFS(Transactions!$F$7:$F$1006,Transactions!$D$7:$D$1006,"Expense",Transactions!$E$7:$E$1006,$B22,Transactions!$I$7:$I$1006,E$6)) | F22: =IF($B22="","",SUMIFS(Transactions!$F$7:$F$1006,Transactions!$D$7:$D$1006,"Expense",Transactions!$E$7:$E$1006,$B22,Transactions!$I$7:$I$1006,F$6)) | G22: =IF($B22="","",SUMIFS(Transactions!$F$7:$F$1006,Transactions!$D$7:$D$1006,"Expense",Transactions!$E$7:$E$1006,$B22,Transactions!$I$7:$I$1006,G$6)) | H22: =IF($B22="","",SUMIFS(Transactions!$F$7:$F$1006,Transactions!$D$7:$D$1006,"Expense",Transactions!$E$7:$E$1006,$B22,Transactions!$I$7:$I$1006,H$6)) | I22: =IF($B22="","",SUMIFS(Transactions!$F$7:$F$1006,Transactions!$D$7:$D$1006,"Expense",Transactions!$E$7:$E$1006,$B22,Transactions!$I$7:$I$1006,I$6)) | J22: =IF($B22="","",SUMIFS(Transactions!$F$7:$F$1006,Transactions!$D$7:$D$1006,"Expense",Transactions!$E$7:$E$1006,$B22,Transactions!$I$7:$I$1006,J$6)) | ... N22: =IF($B22="","",SUMIFS(Transactions!$F$7:$F$1006,Transactions!$D$7:$D$1006,"Expense",Transactions!$E$7:$E$1006,$B22,Transactions!$I$7:$I$1006,N$6)) | O22: =IF($B22="","",SUM(C22:N22)) | P22: =IF($B22="","",IFERROR(O22/MAX(1,COUNTIF(C22:N22,">0")),0))
B23: =IF(Settings!B10="","",Settings!B10) | C23: =IF($B23="","",SUMIFS(Transactions!$F$7:$F$1006,Transactions!$D$7:$D$1006,"Expense",Transactions!$E$7:$E$1006,$B23,Transactions!$I$7:$I$1006,C$6)) | D23: =IF($B23="","",SUMIFS(Transactions!$F$7:$F$1006,Transactions!$D$7:$D$1006,"Expense",Transactions!$E$7:$E$1006,$B23,Transactions!$I$7:$I$1006,D$6)) | E23: =IF($B23="","",SUMIFS(Transactions!$F$7:$F$1006,Transactions!$D$7:$D$1006,"Expense",Transactions!$E$7:$E$1006,$B23,Transactions!$I$7:$I$1006,E$6)) | F23: =IF($B23="","",SUMIFS(Transactions!$F$7:$F$1006,Transactions!$D$7:$D$1006,"Expense",Transactions!$E$7:$E$1006,$B23,Transactions!$I$7:$I$1006,F$6)) | G23: =IF($B23="","",SUMIFS(Transactions!$F$7:$F$1006,Transactions!$D$7:$D$1006,"Expense",Transactions!$E$7:$E$1006,$B23,Transactions!$I$7:$I$1006,G$6)) | H23: =IF($B23="","",SUMIFS(Transactions!$F$7:$F$1006,Transactions!$D$7:$D$1006,"Expense",Transactions!$E$7:$E$1006,$B23,Transactions!$I$7:$I$1006,H$6)) | I23: =IF($B23="","",SUMIFS(Transactions!$F$7:$F$1006,Transactions!$D$7:$D$1006,"Expense",Transactions!$E$7:$E$1006,$B23,Transactions!$I$7:$I$1006,I$6)) | J23: =IF($B23="","",SUMIFS(Transactions!$F$7:$F$1006,Transactions!$D$7:$D$1006,"Expense",Transactions!$E$7:$E$1006,$B23,Transactions!$I$7:$I$1006,J$6)) | ... N23: =IF($B23="","",SUMIFS(Transactions!$F$7:$F$1006,Transactions!$D$7:$D$1006,"Expense",Transactions!$E$7:$E$1006,$B23,Transactions!$I$7:$I$1006,N$6)) | O23: =IF($B23="","",SUM(C23:N23)) | P23: =IF($B23="","",IFERROR(O23/MAX(1,COUNTIF(C23:N23,">0")),0))
B24: =IF(Settings!B11="","",Settings!B11) | C24: =IF($B24="","",SUMIFS(Transactions!$F$7:$F$1006,Transactions!$D$7:$D$1006,"Expense",Transactions!$E$7:$E$1006,$B24,Transactions!$I$7:$I$1006,C$6)) | D24: =IF($B24="","",SUMIFS(Transactions!$F$7:$F$1006,Transactions!$D$7:$D$1006,"Expense",Transactions!$E$7:$E$1006,$B24,Transactions!$I$7:$I$1006,D$6)) | E24: =IF($B24="","",SUMIFS(Transactions!$F$7:$F$1006,Transactions!$D$7:$D$1006,"Expense",Transactions!$E$7:$E$1006,$B24,Transactions!$I$7:$I$1006,E$6)) | F24: =IF($B24="","",SUMIFS(Transactions!$F$7:$F$1006,Transactions!$D$7:$D$1006,"Expense",Transactions!$E$7:$E$1006,$B24,Transactions!$I$7:$I$1006,F$6)) | G24: =IF($B24="","",SUMIFS(Transactions!$F$7:$F$1006,Transactions!$D$7:$D$1006,"Expense",Transactions!$E$7:$E$1006,$B24,Transactions!$I$7:$I$1006,G$6)) | H24: =IF($B24="","",SUMIFS(Transactions!$F$7:$F$1006,Transactions!$D$7:$D$1006,"Expense",Transactions!$E$7:$E$1006,$B24,Transactions!$I$7:$I$1006,H$6)) | I24: =IF($B24="","",SUMIFS(Transactions!$F$7:$F$1006,Transactions!$D$7:$D$1006,"Expense",Transactions!$E$7:$E$1006,$B24,Transactions!$I$7:$I$1006,I$6)) | J24: =IF($B24="","",SUMIFS(Transactions!$F$7:$F$1006,Transactions!$D$7:$D$1006,"Expense",Transactions!$E$7:$E$1006,$B24,Transactions!$I$7:$I$1006,J$6)) | ... N24: =IF($B24="","",SUMIFS(Transactions!$F$7:$F$1006,Transactions!$D$7:$D$1006,"Expense",Transactions!$E$7:$E$1006,$B24,Transactions!$I$7:$I$1006,N$6)) | O24: =IF($B24="","",SUM(C24:N24)) | P24: =IF($B24="","",IFERROR(O24/MAX(1,COUNTIF(C24:N24,">0")),0))
B25: =IF(Settings!B12="","",Settings!B12) | C25: =IF($B25="","",SUMIFS(Transactions!$F$7:$F$1006,Transactions!$D$7:$D$1006,"Expense",Transactions!$E$7:$E$1006,$B25,Transactions!$I$7:$I$1006,C$6)) | D25: =IF($B25="","",SUMIFS(Transactions!$F$7:$F$1006,Transactions!$D$7:$D$1006,"Expense",Transactions!$E$7:$E$1006,$B25,Transactions!$I$7:$I$1006,D$6)) | E25: =IF($B25="","",SUMIFS(Transactions!$F$7:$F$1006,Transactions!$D$7:$D$1006,"Expense",Transactions!$E$7:$E$1006,$B25,Transactions!$I$7:$I$1006,E$6)) | F25: =IF($B25="","",SUMIFS(Transactions!$F$7:$F$1006,Transactions!$D$7:$D$1006,"Expense",Transactions!$E$7:$E$1006,$B25,Transactions!$I$7:$I$1006,F$6)) | G25: =IF($B25="","",SUMIFS(Transactions!$F$7:$F$1006,Transactions!$D$7:$D$1006,"Expense",Transactions!$E$7:$E$1006,$B25,Transactions!$I$7:$I$1006,G$6)) | H25: =IF($B25="","",SUMIFS(Transactions!$F$7:$F$1006,Transactions!$D$7:$D$1006,"Expense",Transactions!$E$7:$E$1006,$B25,Transactions!$I$7:$I$1006,H$6)) | I25: =IF($B25="","",SUMIFS(Transactions!$F$7:$F$1006,Transactions!$D$7:$D$1006,"Expense",Transactions!$E$7:$E$1006,$B25,Transactions!$I$7:$I$1006,I$6)) | J25: =IF($B25="","",SUMIFS(Transactions!$F$7:$F$1006,Transactions!$D$7:$D$1006,"Expense",Transactions!$E$7:$E$1006,$B25,Transactions!$I$7:$I$1006,J$6)) | ... N25: =IF($B25="","",SUMIFS(Transactions!$F$7:$F$1006,Transactions!$D$7:$D$1006,"Expense",Transactions!$E$7:$E$1006,$B25,Transactions!$I$7:$I$1006,N$6)) | O25: =IF($B25="","",SUM(C25:N25)) | P25: =IF($B25="","",IFERROR(O25/MAX(1,COUNTIF(C25:N25,">0")),0))
B26: =IF(Settings!B13="","",Settings!B13) | C26: =IF($B26="","",SUMIFS(Transactions!$F$7:$F$1006,Transactions!$D$7:$D$1006,"Expense",Transactions!$E$7:$E$1006,$B26,Transactions!$I$7:$I$1006,C$6)) | D26: =IF($B26="","",SUMIFS(Transactions!$F$7:$F$1006,Transactions!$D$7:$D$1006,"Expense",Transactions!$E$7:$E$1006,$B26,Transactions!$I$7:$I$1006,D$6)) | E26: =IF($B26="","",SUMIFS(Transactions!$F$7:$F$1006,Transactions!$D$7:$D$1006,"Expense",Transactions!$E$7:$E$1006,$B26,Transactions!$I$7:$I$1006,E$6)) | F26: =IF($B26="","",SUMIFS(Transactions!$F$7:$F$1006,Transactions!$D$7:$D$1006,"Expense",Transactions!$E$7:$E$1006,$B26,Transactions!$I$7:$I$1006,F$6)) | G26: =IF($B26="","",SUMIFS(Transactions!$F$7:$F$1006,Transactions!$D$7:$D$1006,"Expense",Transactions!$E$7:$E$1006,$B26,Transactions!$I$7:$I$1006,G$6)) | H26: =IF($B26="","",SUMIFS(Transactions!$F$7:$F$1006,Transactions!$D$7:$D$1006,"Expense",Transactions!$E$7:$E$1006,$B26,Transactions!$I$7:$I$1006,H$6)) | I26: =IF($B26="","",SUMIFS(Transactions!$F$7:$F$1006,Transactions!$D$7:$D$1006,"Expense",Transactions!$E$7:$E$1006,$B26,Transactions!$I$7:$I$1006,I$6)) | J26: =IF($B26="","",SUMIFS(Transactions!$F$7:$F$1006,Transactions!$D$7:$D$1006,"Expense",Transactions!$E$7:$E$1006,$B26,Transactions!$I$7:$I$1006,J$6)) | ... N26: =IF($B26="","",SUMIFS(Transactions!$F$7:$F$1006,Transactions!$D$7:$D$1006,"Expense",Transactions!$E$7:$E$1006,$B26,Transactions!$I$7:$I$1006,N$6)) | O26: =IF($B26="","",SUM(C26:N26)) | P26: =IF($B26="","",IFERROR(O26/MAX(1,COUNTIF(C26:N26,">0")),0))
B27: =IF(Settings!B14="","",Settings!B14) | C27: =IF($B27="","",SUMIFS(Transactions!$F$7:$F$1006,Transactions!$D$7:$D$1006,"Expense",Transactions!$E$7:$E$1006,$B27,Transactions!$I$7:$I$1006,C$6)) | D27: =IF($B27="","",SUMIFS(Transactions!$F$7:$F$1006,Transactions!$D$7:$D$1006,"Expense",Transactions!$E$7:$E$1006,$B27,Transactions!$I$7:$I$1006,D$6)) | E27: =IF($B27="","",SUMIFS(Transactions!$F$7:$F$1006,Transactions!$D$7:$D$1006,"Expense",Transactions!$E$7:$E$1006,$B27,Transactions!$I$7:$I$1006,E$6)) | F27: =IF($B27="","",SUMIFS(Transactions!$F$7:$F$1006,Transactions!$D$7:$D$1006,"Expense",Transactions!$E$7:$E$1006,$B27,Transactions!$I$7:$I$1006,F$6)) | G27: =IF($B27="","",SUMIFS(Transactions!$F$7:$F$1006,Transactions!$D$7:$D$1006,"Expense",Transactions!$E$7:$E$1006,$B27,Transactions!$I$7:$I$1006,G$6)) | H27: =IF($B27="","",SUMIFS(Transactions!$F$7:$F$1006,Transactions!$D$7:$D$1006,"Expense",Transactions!$E$7:$E$1006,$B27,Transactions!$I$7:$I$1006,H$6)) | I27: =IF($B27="","",SUMIFS(Transactions!$F$7:$F$1006,Transactions!$D$7:$D$1006,"Expense",Transactions!$E$7:$E$1006,$B27,Transactions!$I$7:$I$1006,I$6)) | J27: =IF($B27="","",SUMIFS(Transactions!$F$7:$F$1006,Transactions!$D$7:$D$1006,"Expense",Transactions!$E$7:$E$1006,$B27,Transactions!$I$7:$I$1006,J$6)) | ... N27: =IF($B27="","",SUMIFS(Transactions!$F$7:$F$1006,Transactions!$D$7:$D$1006,"Expense",Transactions!$E$7:$E$1006,$B27,Transactions!$I$7:$I$1006,N$6)) | O27: =IF($B27="","",SUM(C27:N27)) | P27: =IF($B27="","",IFERROR(O27/MAX(1,COUNTIF(C27:N27,">0")),0))
